<?xml version="1.0"?>
<robot name="two_dof_arm">

  <link name="world"/>

  <link name="base_link">
    <inertial>
      <mass value="10.0"/>
      <origin xyz="0 0 0.1" rpy="0 0 0"/>
      <inertia ixx="0.1" ixy="0" ixz="0" iyy="0.1" iyz="0" izz="0.1"/>
    </inertial>
    <visual>
      <geometry>
        <cylinder radius="0.2" length="0.2"/>
      </geometry>
    </visual>
    <collision>
      <geometry>
        <cylinder radius="0.2" length="0.2"/>
      </geometry>
    </collision>
  </link>

  <joint name="world_to_base" type="fixed">
    <parent link="world"/>
    <child link="base_link"/>
    <origin xyz="0 0 0.1" rpy="0 0 0"/>
  </joint>

  <link name="link_1">
    <inertial>
      <mass value="2.0"/>
      <origin xyz="0 0 0.5" rpy="0 0 0"/>
      <inertia ixx="0.05" ixy="0" ixz="0" iyy="0.05" iyz="0" izz="0.01"/>
    </inertial>
    <visual>
      <origin xyz="0 0 0.5" rpy="0 0 0"/>
      <geometry>
        <box size="0.1 0.1 1.0"/>
      </geometry>
    </visual>
    <collision>
      <origin xyz="0 0 0.5" rpy="0 0 0"/>
      <geometry>
        <box size="0.1 0.1 1.0"/>
      </geometry>
    </collision>
  </link>

  <joint name="joint1" type="revolute">
    <parent link="base_link"/>
    <child link="link_1"/>
    <origin xyz="0 0 0.1" rpy="0 0 0"/>
    <axis xyz="0 0 1"/>
    <limit lower="-3.14159" upper="3.14159" effort="100.0" velocity="2.0"/>
  </joint>

  <link name="link_2">
    <inertial>
      <mass value="1.5"/>
      <origin xyz="0 0 0.4" rpy="0 0 0"/>
      <inertia ixx="0.04" ixy="0" ixz="0" iyy="0.04" iyz="0" izz="0.01"/>
    </inertial>
    <visual>
      <origin xyz="0 0 0.4" rpy="0 0 0"/>
      <geometry>
        <box size="0.08 0.08 0.8"/>
      </geometry>
    </visual>
    <collision>
      <origin xyz="0 0 0.4" rpy="0 0 0"/>
      <geometry>
        <box size="0.08 0.08 0.8"/>
      </geometry>
    </collision>
  </link>

  <joint name="joint2" type="revolute">
    <parent link="link_1"/>
    <child link="link_2"/>
    <origin xyz="0 0 1.0" rpy="0 0 0"/>
    <axis xyz="0 1 0"/>
    <limit lower="-1.57" upper="1.57" effort="100.0" velocity="2.0"/>
  </joint>

  <ros2_control name="GazeboSystem" type="system">
    <hardware>
      <plugin>gazebo_ros2_control/GazeboSystem</plugin>
    </hardware>
    <joint name="joint1">
      <command_interface name="position">
        <param name="min">-3.14</param>
        <param name="max">3.14</param>
      </command_interface>
      <state_interface name="position"/>
    </joint>
    <joint name="joint2">
      <command_interface name="position">
        <param name="min">-1.57</param>
        <param name="max">1.57</param>
      </command_interface>
      <state_interface name="position"/>
    </joint>
  </ros2_control>

  <gazebo>
    <plugin name="gazebo_ros2_control" filename="libgazebo_ros2_control.so">
      <parameters>$(find two_dof_arm_simulation)/config/controllers.yaml</parameters>
    </plugin>
  </gazebo>

</robot>
